<?xml version="1.0"?>
<robot name="panda_sim" xmlns:xacro="http://www.ros.org/wiki/xacro">
  <xacro:arg name="name" default="panda"/>
  <xacro:arg name="prefix" default=""/>
  <xacro:arg name="controllers_file" default=""/>

  <xacro:property name="name" value="$(arg name)"/>
  <xacro:property name="prefix" value="$(arg prefix)"/>

  <material name="panda_white">
    <color rgba="0.95 0.95 0.95 1.0"/>
  </material>

  <link name="${prefix}panda_link0">
    <visual>
      <geometry>
        <mesh filename="package://moveit_resources_panda_description/meshes/visual/link0.dae"/>
      </geometry>
      <material name="panda_white"/>
    </visual>
    <collision>
      <geometry>
        <mesh filename="package://moveit_resources_panda_description/meshes/collision/link0.stl"/>
      </geometry>
    </collision>
    <inertial>
      <origin xyz="-0.041018 -0.00014 0.049974" rpy="0 0 0"/>
      <mass value="0.629769"/>
      <inertia ixx="0.00315" ixy="0.00000082904" ixz="0.00015" iyy="0.00388" iyz="0.0000082299" izz="0.004285"/>
    </inertial>
  </link>

  <link name="${prefix}panda_link1">
    <visual>
      <geometry>
        <mesh filename="package://moveit_resources_panda_description/meshes/visual/link1.dae"/>
      </geometry>
      <material name="panda_white"/>
    </visual>
    <collision>
      <geometry>
        <mesh filename="package://moveit_resources_panda_description/meshes/collision/link1.stl"/>
      </geometry>
    </collision>
    <inertial>
      <origin xyz="0.003875 0.002081 -0.04762" rpy="0 0 0"/>
      <mass value="4.970684"/>
      <inertia ixx="0.70337" ixy="-0.000139" ixz="0.006772" iyy="0.70661" iyz="0.019169" izz="0.009117"/>
    </inertial>
  </link>

  <joint name="${prefix}panda_joint1" type="revolute">
    <origin rpy="0 0 0" xyz="0 0 0.333"/>
    <parent link="${prefix}panda_link0"/>
    <child link="${prefix}panda_link1"/>
    <axis xyz="0 0 1"/>
    <limit effort="87" lower="-2.9671" upper="2.9671" velocity="2.3925"/>
    <dynamics damping="0.3" friction="0.02"/>
  </joint>

  <link name="${prefix}panda_link2">
    <visual>
      <geometry>
        <mesh filename="package://moveit_resources_panda_description/meshes/visual/link2.dae"/>
      </geometry>
      <material name="panda_white"/>
    </visual>
    <collision>
      <geometry>
        <mesh filename="package://moveit_resources_panda_description/meshes/collision/link2.stl"/>
      </geometry>
    </collision>
    <inertial>
      <origin xyz="-0.003141 -0.02872 0.003495" rpy="0 0 0"/>
      <mass value="0.646926"/>
      <inertia ixx="0.007962" ixy="-0.003925" ixz="0.010254" iyy="0.02811" iyz="0.000704" izz="0.025995"/>
    </inertial>
  </link>

  <joint name="${prefix}panda_joint2" type="revolute">
    <origin rpy="-1.57079632679 0 0" xyz="0 0 0"/>
    <parent link="${prefix}panda_link1"/>
    <child link="${prefix}panda_link2"/>
    <axis xyz="0 0 1"/>
    <limit effort="87" lower="-1.8326" upper="1.8326" velocity="2.3925"/>
    <dynamics damping="0.3" friction="0.02"/>
  </joint>

  <link name="${prefix}panda_link3">
    <visual>
      <geometry>
        <mesh filename="package://moveit_resources_panda_description/meshes/visual/link3.dae"/>
      </geometry>
      <material name="panda_white"/>
    </visual>
    <collision>
      <geometry>
        <mesh filename="package://moveit_resources_panda_description/meshes/collision/link3.stl"/>
      </geometry>
    </collision>
    <inertial>
      <origin xyz="0.027518 0.039252 -0.066502" rpy="0 0 0"/>
      <mass value="3.228604"/>
      <inertia ixx="0.037242" ixy="-0.004761" ixz="-0.011396" iyy="0.036155" iyz="-0.012805" izz="0.01083"/>
    </inertial>
  </link>

  <joint name="${prefix}panda_joint3" type="revolute">
    <origin rpy="1.57079632679 0 0" xyz="0 -0.316 0"/>
    <parent link="${prefix}panda_link2"/>
    <child link="${prefix}panda_link3"/>
    <axis xyz="0 0 1"/>
    <limit effort="87" lower="-2.9671" upper="2.9671" velocity="2.3925"/>
    <dynamics damping="0.3" friction="0.02"/>
  </joint>

  <link name="${prefix}panda_link4">
    <visual>
      <geometry>
        <mesh filename="package://moveit_resources_panda_description/meshes/visual/link4.dae"/>
      </geometry>
      <material name="panda_white"/>
    </visual>
    <collision>
      <geometry>
        <mesh filename="package://moveit_resources_panda_description/meshes/collision/link4.stl"/>
      </geometry>
    </collision>
    <inertial>
      <origin xyz="-0.05317 0.104419 0.027454" rpy="0 0 0"/>
      <mass value="3.587895"/>
      <inertia ixx="0.025853" ixy="0.007796" ixz="-0.001332" iyy="0.019552" iyz="0.008641" izz="0.028323"/>
    </inertial>
  </link>

  <joint name="${prefix}panda_joint4" type="revolute">
    <origin rpy="1.57079632679 0 0" xyz="0.0825 0 0"/>
    <parent link="${prefix}panda_link3"/>
    <child link="${prefix}panda_link4"/>
    <axis xyz="0 0 1"/>
    <limit effort="87" lower="-3.1416" upper="0.0873" velocity="2.3925"/>
    <dynamics damping="0.25" friction="0.02"/>
  </joint>

  <link name="${prefix}panda_link5">
    <visual>
      <geometry>
        <mesh filename="package://moveit_resources_panda_description/meshes/visual/link5.dae"/>
      </geometry>
      <material name="panda_white"/>
    </visual>
    <collision>
      <geometry>
        <mesh filename="package://moveit_resources_panda_description/meshes/collision/link5.stl"/>
      </geometry>
    </collision>
    <inertial>
      <origin xyz="-0.011953 0.041065 -0.038437" rpy="0 0 0"/>
      <mass value="1.225946"/>
      <inertia ixx="0.035549" ixy="-0.002117" ixz="-0.004037" iyy="0.029474" iyz="0.000229" izz="0.008627"/>
    </inertial>
  </link>

  <joint name="${prefix}panda_joint5" type="revolute">
    <origin rpy="-1.57079632679 0 0" xyz="-0.0825 0.384 0"/>
    <parent link="${prefix}panda_link4"/>
    <child link="${prefix}panda_link5"/>
    <axis xyz="0 0 1"/>
    <limit effort="12" lower="-2.9671" upper="2.9671" velocity="2.871"/>
    <dynamics damping="0.20" friction="0.015"/>
  </joint>

  <link name="${prefix}panda_link6">
    <visual>
      <geometry>
        <mesh filename="package://moveit_resources_panda_description/meshes/visual/link6.dae"/>
      </geometry>
      <material name="panda_white"/>
    </visual>
    <collision>
      <geometry>
        <mesh filename="package://moveit_resources_panda_description/meshes/collision/link6.stl"/>
      </geometry>
    </collision>
    <inertial>
      <origin xyz="0.060149 -0.014117 -0.010517" rpy="0 0 0"/>
      <mass value="1.666555"/>
      <inertia ixx="0.001964" ixy="0.000109" ixz="-0.001158" iyy="0.004354" iyz="0.000341" izz="0.005433"/>
    </inertial>
  </link>

  <joint name="${prefix}panda_joint6" type="revolute">
    <origin rpy="1.57079632679 0 0" xyz="0 0 0"/>
    <parent link="${prefix}panda_link5"/>
    <child link="${prefix}panda_link6"/>
    <axis xyz="0 0 1"/>
    <limit effort="12" lower="-0.0873" upper="3.8223" velocity="2.871"/>
    <dynamics damping="0.20" friction="0.015"/>
  </joint>

  <link name="${prefix}panda_link7">
    <visual>
      <geometry>
        <mesh filename="package://moveit_resources_panda_description/meshes/visual/link7.dae"/>
      </geometry>
      <material name="panda_white"/>
    </visual>
    <collision>
      <geometry>
        <mesh filename="package://moveit_resources_panda_description/meshes/collision/link7.stl"/>
      </geometry>
    </collision>
    <inertial>
      <origin xyz="0.010517 -0.004252 0.061597" rpy="0 0 0"/>
      <mass value="0.735522"/>
      <inertia ixx="0.012516" ixy="-0.000428" ixz="-0.00119" iyy="0.010027" iyz="-0.000741" izz="0.004815"/>
    </inertial>
  </link>

  <joint name="${prefix}panda_joint7" type="revolute">
    <origin rpy="1.57079632679 0 0" xyz="0.088 0 0"/>
    <parent link="${prefix}panda_link6"/>
    <child link="${prefix}panda_link7"/>
    <axis xyz="0 0 1"/>
    <limit effort="12" lower="-2.9671" upper="2.9671" velocity="2.871"/>
    <dynamics damping="0.20" friction="0.015"/>
  </joint>

  <link name="${prefix}panda_link8">
    <visual>
      <origin xyz="0 0 0.0535" rpy="0 0 0"/>
      <geometry>
        <cylinder radius="0.03" length="0.107"/>
      </geometry>
      <material name="panda_white"/>
    </visual>
    <collision>
      <origin xyz="0 0 0.0535" rpy="0 0 0"/>
      <geometry>
        <cylinder radius="0.03" length="0.107"/>
      </geometry>
    </collision>
    <inertial>
      <origin xyz="0 0 0.0535" rpy="0 0 0"/>
      <mass value="0.15"/>
      <inertia ixx="0.0002" ixy="0.0" ixz="0.0" iyy="0.0002" iyz="0.0" izz="0.00005"/>
    </inertial>
  </link>

  <joint name="${prefix}panda_joint8" type="fixed">
    <origin rpy="0 0 0" xyz="0 0 0.107"/>
    <parent link="${prefix}panda_link7"/>
    <child link="${prefix}panda_link8"/>
  </joint>

  <link name="${prefix}panda_tool0"/>
  <joint name="${prefix}panda_tool0_joint" type="fixed">
    <origin xyz="0 0 0" rpy="0 0 0"/>
    <parent link="${prefix}panda_link8"/>
    <child link="${prefix}panda_tool0"/>
  </joint>

  <ros2_control name="${name}_system" type="system">
    <hardware>
      <plugin>gz_ros2_control/GazeboSimSystem</plugin>
    </hardware>

    <joint name="${prefix}panda_joint1">
      <command_interface name="position"/>
      <state_interface name="position"/>
      <state_interface name="velocity"/>
    </joint>
    <joint name="${prefix}panda_joint2">
      <command_interface name="position"/>
      <state_interface name="position"/>
      <state_interface name="velocity"/>
    </joint>
    <joint name="${prefix}panda_joint3">
      <command_interface name="position"/>
      <state_interface name="position"/>
      <state_interface name="velocity"/>
    </joint>
    <joint name="${prefix}panda_joint4">
      <command_interface name="position"/>
      <state_interface name="position"/>
      <state_interface name="velocity"/>
    </joint>
    <joint name="${prefix}panda_joint5">
      <command_interface name="position"/>
      <state_interface name="position"/>
      <state_interface name="velocity"/>
    </joint>
    <joint name="${prefix}panda_joint6">
      <command_interface name="position"/>
      <state_interface name="position"/>
      <state_interface name="velocity"/>
    </joint>
    <joint name="${prefix}panda_joint7">
      <command_interface name="position"/>
      <state_interface name="position"/>
      <state_interface name="velocity"/>
    </joint>
  </ros2_control>

  <transmission name="${prefix}panda_joint1_transmission">
    <type>transmission_interface/SimpleTransmission</type>
    <joint name="${prefix}panda_joint1">
      <hardwareInterface>hardware_interface/PositionJointInterface</hardwareInterface>
    </joint>
    <actuator name="${prefix}panda_joint1_motor">
      <hardwareInterface>hardware_interface/PositionJointInterface</hardwareInterface>
      <mechanicalReduction>1.0</mechanicalReduction>
    </actuator>
  </transmission>

  <transmission name="${prefix}panda_joint2_transmission">
    <type>transmission_interface/SimpleTransmission</type>
    <joint name="${prefix}panda_joint2">
      <hardwareInterface>hardware_interface/PositionJointInterface</hardwareInterface>
    </joint>
    <actuator name="${prefix}panda_joint2_motor">
      <hardwareInterface>hardware_interface/PositionJointInterface</hardwareInterface>
      <mechanicalReduction>1.0</mechanicalReduction>
    </actuator>
  </transmission>

  <transmission name="${prefix}panda_joint3_transmission">
    <type>transmission_interface/SimpleTransmission</type>
    <joint name="${prefix}panda_joint3">
      <hardwareInterface>hardware_interface/PositionJointInterface</hardwareInterface>
    </joint>
    <actuator name="${prefix}panda_joint3_motor">
      <hardwareInterface>hardware_interface/PositionJointInterface</hardwareInterface>
      <mechanicalReduction>1.0</mechanicalReduction>
    </actuator>
  </transmission>

  <transmission name="${prefix}panda_joint4_transmission">
    <type>transmission_interface/SimpleTransmission</type>
    <joint name="${prefix}panda_joint4">
      <hardwareInterface>hardware_interface/PositionJointInterface</hardwareInterface>
    </joint>
    <actuator name="${prefix}panda_joint4_motor">
      <hardwareInterface>hardware_interface/PositionJointInterface</hardwareInterface>
      <mechanicalReduction>1.0</mechanicalReduction>
    </actuator>
  </transmission>

  <transmission name="${prefix}panda_joint5_transmission">
    <type>transmission_interface/SimpleTransmission</type>
    <joint name="${prefix}panda_joint5">
      <hardwareInterface>hardware_interface/PositionJointInterface</hardwareInterface>
    </joint>
    <actuator name="${prefix}panda_joint5_motor">
      <hardwareInterface>hardware_interface/PositionJointInterface</hardwareInterface>
      <mechanicalReduction>1.0</mechanicalReduction>
    </actuator>
  </transmission>

  <transmission name="${prefix}panda_joint6_transmission">
    <type>transmission_interface/SimpleTransmission</type>
    <joint name="${prefix}panda_joint6">
      <hardwareInterface>hardware_interface/PositionJointInterface</hardwareInterface>
    </joint>
    <actuator name="${prefix}panda_joint6_motor">
      <hardwareInterface>hardware_interface/PositionJointInterface</hardwareInterface>
      <mechanicalReduction>1.0</mechanicalReduction>
    </actuator>
  </transmission>

  <transmission name="${prefix}panda_joint7_transmission">
    <type>transmission_interface/SimpleTransmission</type>
    <joint name="${prefix}panda_joint7">
      <hardwareInterface>hardware_interface/PositionJointInterface</hardwareInterface>
    </joint>
    <actuator name="${prefix}panda_joint7_motor">
      <hardwareInterface>hardware_interface/PositionJointInterface</hardwareInterface>
      <mechanicalReduction>1.0</mechanicalReduction>
    </actuator>
  </transmission>

  <gazebo>
    <plugin filename="libgz_ros2_control-system.so" name="gz_ros2_control::GazeboSimROS2ControlPlugin">
      <parameters>$(arg controllers_file)</parameters>
    </plugin>
  </gazebo>
</robot>
